<?xml version="1.0" encoding="utf-8"?>
<!-- This URDF was automatically created by SolidWorks to URDF Exporter! Originally created by Stephen Brawner (brawner@gmail.com) 
     Commit Version: 1.6.0-4-g7f85cfe  Build Version: 1.6.7995.38578
     For more information, please see http://wiki.ros.org/sw_urdf_exporter -->
<robot
  name="ROVER_A1_URDF">
  <link
    name="base_link">
    <inertial>
      <origin
        xyz="-0.0331096533697888 7.09668643295025E-11 0.0694234106628136"
        rpy="0 0 0" />
      <mass
        value="34.5546054764677" />
      <inertia
        ixx="0.239631061537289"
        ixy="-0.000822634814054065"
        ixz="1.94613778104168E-05"
        iyy="0.23053157862469"
        iyz="-7.494352360915E-14"
        izz="0.370168476367055" />
    </inertial>
    <visual>
      <origin
        xyz="0 0 0"
        rpy="0 0 0" />
      <geometry>
        <mesh
          filename="package://ROVER_A1_URDF/meshes/base_link.STL" />
      </geometry>
      <material
        name="">
        <color
          rgba="0 0 0 1" />
      </material>
    </visual>
    <collision>
      <origin
        xyz="0 0 0"
        rpy="0 0 0" />
      <geometry>
        <mesh
          filename="package://ROVER_A1_URDF/meshes/base_link.STL" />
      </geometry>
    </collision>
  </link>
  <link
    name="link_back_left">
    <inertial>
      <origin
        xyz="-4.0546E-07 -0.023234 -5.0256E-06"
        rpy="0 0 0" />
      <mass
        value="7.0121" />
      <inertia
        ixx="0.038546"
        ixy="-1.2025E-09"
        ixz="3.0286E-08"
        iyy="0.070059"
        iyz="-2.0696E-10"
        izz="0.038546" />
    </inertial>
    <visual>
      <origin
        xyz="0 0 0"
        rpy="0 0 0" />
      <geometry>
        <mesh
          filename="package://ROVER_A1_URDF/meshes/link_back_left.STL" />
      </geometry>
      <material
        name="">
        <color
          rgba="0.75294 0.75294 0.75294 1" />
      </material>
    </visual>
    <collision>
      <origin
        xyz="0 0 0"
        rpy="0 0 0" />
      <geometry>
        <mesh
          filename="package://ROVER_A1_URDF/meshes/link_back_left.STL" />
      </geometry>
    </collision>
  </link>
  <joint
    name="joint_back_left"
    type="continuous">
    <origin
      xyz="-0.25123 0.31801 0.02474"
      rpy="0 0 0" />
    <parent
      link="base_link" />
    <child
      link="link_back_left" />
    <axis
      xyz="0 1 0" />
  </joint>
  <link
    name="link_back_right">
    <inertial>
      <origin
        xyz="-1.6507E-06 0.023234 -4.7641E-06"
        rpy="0 0 0" />
      <mass
        value="7.0121" />
      <inertia
        ixx="0.038546"
        ixy="-1.0203E-09"
        ixz="1.0032E-07"
        iyy="0.070059"
        iyz="6.7262E-10"
        izz="0.038546" />
    </inertial>
    <visual>
      <origin
        xyz="0 0 0"
        rpy="0 0 0" />
      <geometry>
        <mesh
          filename="package://ROVER_A1_URDF/meshes/link_back_right.STL" />
      </geometry>
      <material
        name="">
        <color
          rgba="0.75294 0.75294 0.75294 1" />
      </material>
    </visual>
    <collision>
      <origin
        xyz="0 0 0"
        rpy="0 0 0" />
      <geometry>
        <mesh
          filename="package://ROVER_A1_URDF/meshes/link_back_right.STL" />
      </geometry>
    </collision>
  </link>
  <joint
    name="joint_back_right"
    type="continuous">
    <origin
      xyz="-0.25123 -0.31801 0.02474"
      rpy="0 0 0" />
    <parent
      link="base_link" />
    <child
      link="link_back_right" />
    <axis
      xyz="0 1 0" />
  </joint>
  <link
    name="link_front_right">
    <inertial>
      <origin
        xyz="-4.0956E-06 0.023234 -2.9405E-06"
        rpy="0 0 0" />
      <mass
        value="7.0121" />
      <inertia
        ixx="0.038546"
        ixy="-4.383E-10"
        ixz="1.5915E-07"
        iyy="0.070059"
        iyz="1.1419E-09"
        izz="0.038546" />
    </inertial>
    <visual>
      <origin
        xyz="0 0 0"
        rpy="0 0 0" />
      <geometry>
        <mesh
          filename="package://ROVER_A1_URDF/meshes/link_front_right.STL" />
      </geometry>
      <material
        name="">
        <color
          rgba="0.75294 0.75294 0.75294 1" />
      </material>
    </visual>
    <collision>
      <origin
        xyz="0 0 0"
        rpy="0 0 0" />
      <geometry>
        <mesh
          filename="package://ROVER_A1_URDF/meshes/link_front_right.STL" />
      </geometry>
    </collision>
  </link>
  <joint
    name="joint_front_right"
    type="continuous">
    <origin
      xyz="0.25117 -0.31801 0.02474"
      rpy="0 0 0" />
    <parent
      link="base_link" />
    <child
      link="link_front_right" />
    <axis
      xyz="0 1 0" />
  </joint>
  <link
    name="link_front_left">
    <inertial>
      <origin
        xyz="-3.3863E-06 -0.023234 3.7355E-06"
        rpy="0 0 0" />
      <mass
        value="7.0121" />
      <inertia
        ixx="0.038546"
        ixy="6.7515E-10"
        ixz="-1.6558E-07"
        iyy="0.070059"
        iyz="1.021E-09"
        izz="0.038546" />
    </inertial>
    <visual>
      <origin
        xyz="0 0 0"
        rpy="0 0 0" />
      <geometry>
        <mesh
          filename="package://ROVER_A1_URDF/meshes/link_front_left.STL" />
      </geometry>
      <material
        name="">
        <color
          rgba="0.75294 0.75294 0.75294 1" />
      </material>
    </visual>
    <collision>
      <origin
        xyz="0 0 0"
        rpy="0 0 0" />
      <geometry>
        <mesh
          filename="package://ROVER_A1_URDF/meshes/link_front_left.STL" />
      </geometry>
    </collision>
  </link>
  <joint
    name="joint_front_left"
    type="continuous">
    <origin
      xyz="0.25117 0.31801 0.02474"
      rpy="0 0 0" />
    <parent
      link="base_link" />
    <child
      link="link_front_left" />
    <axis
      xyz="0 1 0" />
  </joint>
</robot>